Workbook
Name cal.year: Customizations!$C$4
Name holiday_dates: holidays[Date]
Name icon_types: icons[Type]
Name month.nums: Calc!$C$13:$C$84
Name monthly.calendar: Calc!$D$13:$J$84
Name months.list: _xlfn.ANCHORARRAY(Calc!$V$13)
Name planner_dates: Plan[Date]
Name show.planner: Customizations!$C$7
Name week.start: Customizations!$C$5
Name weekend.type: Customizations!$C$6

Sheet Calendar
C1: Calendar & Planner Template (2024)
C4: =cal.year&" Calendar" -> 2024 Calendar | AI4: Upcoming Activities
C6: 1 | D6: =TEXT(C9,"MMMM") -> January | K6: 2 | L6: =TEXT(K9,"MMMM") -> February | S6: 3 | T6: =TEXT(S9,"MMMM") -> March | AA6: 4 | AB6: =TEXT(AA9,"MMMM") -> April | AI6: =Calc!R13 -> 👨‍👧‍👦 | AJ6: =Calc!S13 -> 29-Jan: School Reopens
C7: =LEFT(TEXT(C9,"DDD"),1) -> M | D7: =LEFT(TEXT(D9,"DDD"),1) -> T | E7: =LEFT(TEXT(E9,"DDD"),1) -> W | F7: =LEFT(TEXT(F9,"DDD"),1) -> T | G7: =LEFT(TEXT(G9,"DDD"),1) -> F | H7: =LEFT(TEXT(H9,"DDD"),1) -> S | I7: =LEFT(TEXT(I9,"DDD"),1) -> S | K7: =LEFT(TEXT(K9,"DDD"),1) -> M | L7: =LEFT(TEXT(L9,"DDD"),1) -> T | M7: =LEFT(TEXT(M9,"DDD"),1) -> W | N7: =LEFT(TEXT(N9,"DDD"),1) -> T | O7: =LEFT(TEXT(O9,"DDD"),1) -> F | P7: =LEFT(TEXT(P9,"DDD"),1) -> S | Q7: =LEFT(TEXT(Q9,"DDD"),1) -> S | S7: =LEFT(TEXT(S9,"DDD"),1) -> M | T7: =LEFT(TEXT(T9,"DDD"),1) -> T | U7: =LEFT(TEXT(U9,"DDD"),1) -> W | V7: =LEFT(TEXT(V9,"DDD"),1) -> T | W7: =LEFT(TEXT(W9,"DDD"),1) -> F | X7: =LEFT(TEXT(X9,"DDD"),1) -> S | Y7: =LEFT(TEXT(Y9,"DDD"),1) -> S | AA7: =LEFT(TEXT(AA9,"DDD"),1) -> M | AB7: =LEFT(TEXT(AB9,"DDD"),1) -> T | AC7: =LEFT(TEXT(AC9,"DDD"),1) -> W | AD7: =LEFT(TEXT(AD9,"DDD"),1) -> T | AE7: =LEFT(TEXT(AE9,"DDD"),1) -> F | AF7: =LEFT(TEXT(AF9,"DDD"),1) -> S | AG7: =LEFT(TEXT(AG9,"DDD"),1) -> S | AI7: =Calc!R14 -> ⏱ | AJ7: =Calc!S14 -> 29-Jan: Order Team Lunches
C8: {=_xlfn.LET(_xlpm.dt, _xlfn._xlws.FILTER(monthly.calendar, month.nums=C6), IF(MONTH(_xlpm.dt)<>C6,"",_xlpm.dt))} -> 45292 | D8: 45293 | E8: 45294 | F8: 45295 | G8: 45296 | H8: 45297 | I8: 45298 | K8: {=_xlfn.LET(_xlpm.dt, _xlfn._xlws.FILTER(monthly.calendar, month.nums=K6), IF(MONTH(_xlpm.dt)<>K6,"",_xlpm.dt))} | N8: 45323 | O8: 45324 | P8: 45325 | Q8: 45326 | S8: {=_xlfn.LET(_xlpm.dt, _xlfn._xlws.FILTER(monthly.calendar, month.nums=S6), IF(MONTH(_xlpm.dt)<>S6,"",_xlpm.dt))} | W8: 45352 | X8: 45353 | Y8: 45354 | AA8: {=_xlfn.LET(_xlpm.dt, _xlfn._xlws.FILTER(monthly.calendar, month.nums=AA6), IF(MONTH(_xlpm.dt)<>AA6,"",_xlpm.dt))} -> 45383 | AB8: 45384 | AC8: 45385 | AD8: 45386 | AE8: 45387 | AF8: 45388 | AG8: 45389 | AI8: =Calc!R15 -> 🏢 | AJ8: =Calc!S15 -> 6-Feb: Flight to London
C9: 45299 | D9: 45300 | E9: 45301 | F9: 45302 | G9: 45303 | H9: 45304 | I9: 45305 | K9: 45327 | L9: 45328 | M9: 45329 | N9: 45330 | O9: 45331 | P9: 45332 | Q9: 45333 | S9: 45355 | T9: 45356 | U9: 45357 | V9: 45358 | W9: 45359 | X9: 45360 | Y9: 45361 | AA9: 45390 | AB9: 45391 | AC9: 45392 | AD9: 45393 | AE9: 45394 | AF9: 45395 | AG9: 45396 | AI9: =Calc!R16 -> ⏱ | AJ9: =Calc!S16 -> 26-Feb: University Term Starts
C10: 45306 | D10: 45307 | E10: 45308 | F10: 45309 | G10: 45310 | H10: 45311 | I10: 45312 | K10: 45334 | L10: 45335 | M10: 45336 | N10: 45337 | O10: 45338 | P10: 45339 | Q10: 45340 | S10: 45362 | T10: 45363 | U10: 45364 | V10: 45365 | W10: 45366 | X10: 45367 | Y10: 45368 | AA10: 45397 | AB10: 45398 | AC10: 45399 | AD10: 45400 | AE10: 45401 | AF10: 45402 | AG10: 45403 | AI10: =Calc!R17 -> 🎉 | AJ10: =Calc!S17 -> 13-Apr: Term Break
C11: 45313 | D11: 45314 | E11: 45315 | F11: 45316 | G11: 45317 | H11: 45318 | I11: 45319 | K11: 45341 | L11: 45342 | M11: 45343 | N11: 45344 | O11: 45345 | P11: 45346 | Q11: 45347 | S11: 45369 | T11: 45370 | U11: 45371 | V11: 45372 | W11: 45373 | X11: 45374 | Y11: 45375 | AA11: 45404 | AB11: 45405 | AC11: 45406 | AD11: 45407 | AE11: 45408 | AF11: 45409 | AG11: 45410 | AI11: =Calc!R18 -> ✈ | AJ11: =Calc!S18 -> 6-Jul: Fiji Holiday
C12: 45320 | D12: 45321 | E12: 45322 | K12: 45348 | L12: 45349 | M12: 45350 | N12: 45351 | S12: 45376 | T12: 45377 | U12: 45378 | V12: 45379 | W12: 45380 | X12: 45381 | Y12: 45382 | AA12: 45411 | AB12: 45412 | AI12: =Calc!R19 -> 🎂 | AJ12: =Calc!S19 -> 24-Sep: Kids Birthday
AI13: =Calc!R20 | AJ13: =Calc!S20
AI14: =Calc!R21 | AJ14: =Calc!S21
C15: 5 | D15: =TEXT(C18,"MMMM") -> May | K15: 6 | L15: =TEXT(K18,"MMMM") -> June | S15: 7 | T15: =TEXT(S18,"MMMM") -> July | AA15: 8 | AB15: =TEXT(AA18,"MMMM") -> August | AI15: =Calc!R22 | AJ15: =Calc!S22
C16: =LEFT(TEXT(C18,"DDD"),1) -> M | D16: =LEFT(TEXT(D18,"DDD"),1) -> T | E16: =LEFT(TEXT(E18,"DDD"),1) -> W | F16: =LEFT(TEXT(F18,"DDD"),1) -> T | G16: =LEFT(TEXT(G18,"DDD"),1) -> F | H16: =LEFT(TEXT(H18,"DDD"),1) -> S | I16: =LEFT(TEXT(I18,"DDD"),1) -> S | K16: =LEFT(TEXT(K18,"DDD"),1) -> M | L16: =LEFT(TEXT(L18,"DDD"),1) -> T | M16: =LEFT(TEXT(M18,"DDD"),1) -> W | N16: =LEFT(TEXT(N18,"DDD"),1) -> T | O16: =LEFT(TEXT(O18,"DDD"),1) -> F | P16: =LEFT(TEXT(P18,"DDD"),1) -> S | Q16: =LEFT(TEXT(Q18,"DDD"),1) -> S | S16: =LEFT(TEXT(S18,"DDD"),1) -> M | T16: =LEFT(TEXT(T18,"DDD"),1) -> T | U16: =LEFT(TEXT(U18,"DDD"),1) -> W | V16: =LEFT(TEXT(V18,"DDD"),1) -> T | W16: =LEFT(TEXT(W18,"DDD"),1) -> F | X16: =LEFT(TEXT(X18,"DDD"),1) -> S | Y16: =LEFT(TEXT(Y18,"DDD"),1) -> S | AA16: =LEFT(TEXT(AA18,"DDD"),1) -> M | AB16: =LEFT(TEXT(AB18,"DDD"),1) -> T | AC16: =LEFT(TEXT(AC18,"DDD"),1) -> W | AD16: =LEFT(TEXT(AD18,"DDD"),1) -> T | AE16: =LEFT(TEXT(AE18,"DDD"),1) -> F | AF16: =LEFT(TEXT(AF18,"DDD"),1) -> S | AG16: =LEFT(TEXT(AG18,"DDD"),1) -> S | AI16: =Calc!R23 | AJ16: =Calc!S23
C17: {=_xlfn.LET(_xlpm.dt, _xlfn._xlws.FILTER(monthly.calendar, month.nums=C15), IF(MONTH(_xlpm.dt)<>C15,"",_xlpm.dt))} | E17: 45413 | F17: 45414 | G17: 45415 | H17: 45416 | I17: 45417 | K17: {=_xlfn.LET(_xlpm.dt, _xlfn._xlws.FILTER(monthly.calendar, month.nums=K15), IF(MONTH(_xlpm.dt)<>K15,"",_xlpm.dt))} | P17: 45444 | Q17: 45445 | S17: {=_xlfn.LET(_xlpm.dt, _xlfn._xlws.FILTER(monthly.calendar, month.nums=S15), IF(MONTH(_xlpm.dt)<>S15,"",_xlpm.dt))} -> 45474 | T17: 45475 | U17: 45476 | V17: 45477 | W17: 45478 | X17: 45479 | Y17: 45480 | AA17: {=_xlfn.LET(_xlpm.dt, _xlfn._xlws.FILTER(monthly.calendar, month.nums=AA15), IF(MONTH(_xlpm.dt)<>AA15,"",_xlpm.dt))} | AD17: 45505 | AE17: 45506 | AF17: 45507 | AG17: 45508 | AI17: =Calc!R24 | AJ17: =Calc!S24
C18: 45418 | D18: 45419 | E18: 45420 | F18: 45421 | G18: 45422 | H18: 45423 | I18: 45424 | K18: 45446 | L18: 45447 | M18: 45448 | N18: 45449 | O18: 45450 | P18: 45451 | Q18: 45452 | S18: 45481 | T18: 45482 | U18: 45483 | V18: 45484 | W18: 45485 | X18: 45486 | Y18: 45487 | AA18: 45509 | AB18: 45510 | AC18: 45511 | AD18: 45512 | AE18: 45513 | AF18: 45514 | AG18: 45515 | AI18: =Calc!R25 | AJ18: =Calc!S25
C19: 45425 | D19: 45426 | E19: 45427 | F19: 45428 | G19: 45429 | H19: 45430 | I19: 45431 | K19: 45453 | L19: 45454 | M19: 45455 | N19: 45456 | O19: 45457 | P19: 45458 | Q19: 45459 | S19: 45488 | T19: 45489 | U19: 45490 | V19: 45491 | W19: 45492 | X19: 45493 | Y19: 45494 | AA19: 45516 | AB19: 45517 | AC19: 45518 | AD19: 45519 | AE19: 45520 | AF19: 45521 | AG19: 45522 | AI19: =Calc!R26 | AJ19: =Calc!S26
C20: 45432 | D20: 45433 | E20: 45434 | F20: 45435 | G20: 45436 | H20: 45437 | I20: 45438 | K20: 45460 | L20: 45461 | M20: 45462 | N20: 45463 | O20: 45464 | P20: 45465 | Q20: 45466 | S20: 45495 | T20: 45496 | U20: 45497 | V20: 45498 | W20: 45499 | X20: 45500 | Y20: 45501 | AA20: 45523 | AB20: 45524 | AC20: 45525 | AD20: 45526 | AE20: 45527 | AF20: 45528 | AG20: 45529 | AI20: =Calc!R27 | AJ20: =Calc!S27
C21: 45439 | D21: 45440 | E21: 45441 | F21: 45442 | G21: 45443 | K21: 45467 | L21: 45468 | M21: 45469 | N21: 45470 | O21: 45471 | P21: 45472 | Q21: 45473 | S21: 45502 | T21: 45503 | U21: 45504 | AA21: 45530 | AB21: 45531 | AC21: 45532 | AD21: 45533 | AE21: 45534 | AF21: 45535 | AI21: =Calc!R28 | AJ21: =Calc!S28
AI22: =Calc!R29 | AJ22: =Calc!S29
AI23: =Calc!R30 | AJ23: =Calc!S30
C24: 9 | D24: =TEXT(C27,"MMMM") -> September | K24: 10 | L24: =TEXT(K27,"MMMM") -> October | S24: 11 | T24: =TEXT(S27,"MMMM") -> November | AA24: 12 | AB24: =TEXT(AA27,"MMMM") -> December | AI24: =Calc!R31 | AJ24: =Calc!S31
C25: =LEFT(TEXT(C27,"DDD"),1) -> M | D25: =LEFT(TEXT(D27,"DDD"),1) -> T | E25: =LEFT(TEXT(E27,"DDD"),1) -> W | F25: =LEFT(TEXT(F27,"DDD"),1) -> T | G25: =LEFT(TEXT(G27,"DDD"),1) -> F | H25: =LEFT(TEXT(H27,"DDD"),1) -> S | I25: =LEFT(TEXT(I27,"DDD"),1) -> S | K25: =LEFT(TEXT(K27,"DDD"),1) -> M | L25: =LEFT(TEXT(L27,"DDD"),1) -> T | M25: =LEFT(TEXT(M27,"DDD"),1) -> W | N25: =LEFT(TEXT(N27,"DDD"),1) -> T | O25: =LEFT(TEXT(O27,"DDD"),1) -> F | P25: =LEFT(TEXT(P27,"DDD"),1) -> S | Q25: =LEFT(TEXT(Q27,"DDD"),1) -> S | S25: =LEFT(TEXT(S27,"DDD"),1) -> M | T25: =LEFT(TEXT(T27,"DDD"),1) -> T | U25: =LEFT(TEXT(U27,"DDD"),1) -> W | V25: =LEFT(TEXT(V27,"DDD"),1) -> T | W25: =LEFT(TEXT(W27,"DDD"),1) -> F | X25: =LEFT(TEXT(X27,"DDD"),1) -> S | Y25: =LEFT(TEXT(Y27,"DDD"),1) -> S | AA25: =LEFT(TEXT(AA27,"DDD"),1) -> M | AB25: =LEFT(TEXT(AB27,"DDD"),1) -> T | AC25: =LEFT(TEXT(AC27,"DDD"),1) -> W | AD25: =LEFT(TEXT(AD27,"DDD"),1) -> T | AE25: =LEFT(TEXT(AE27,"DDD"),1) -> F | AF25: =LEFT(TEXT(AF27,"DDD"),1) -> S | AG25: =LEFT(TEXT(AG27,"DDD"),1) -> S | AI25: =Calc!R32 | AJ25: =Calc!S32
C26: {=_xlfn.LET(_xlpm.dt, _xlfn._xlws.FILTER(monthly.calendar, month.nums=C24), IF(MONTH(_xlpm.dt)<>C24,"",_xlpm.dt))} | I26: 45536 | K26: {=_xlfn.LET(_xlpm.dt, _xlfn._xlws.FILTER(monthly.calendar, month.nums=K24), IF(MONTH(_xlpm.dt)<>K24,"",_xlpm.dt))} | L26: 45566 | M26: 45567 | N26: 45568 | O26: 45569 | P26: 45570 | Q26: 45571 | S26: {=_xlfn.LET(_xlpm.dt, _xlfn._xlws.FILTER(monthly.calendar, month.nums=S24), IF(MONTH(_xlpm.dt)<>S24,"",_xlpm.dt))} | W26: 45597 | X26: 45598 | Y26: 45599 | AA26: {=_xlfn.LET(_xlpm.dt, _xlfn._xlws.FILTER(monthly.calendar, month.nums=AA24), IF(MONTH(_xlpm.dt)<>AA24,"",_xlpm.dt))} | AG26: 45627 | AI26: =Calc!R33 | AJ26: =Calc!S33
C27: 45537 | D27: 45538 | E27: 45539 | F27: 45540 | G27: 45541 | H27: 45542 | I27: 45543 | K27: 45572 | L27: 45573 | M27: 45574 | N27: 45575 | O27: 45576 | P27: 45577 | Q27: 45578 | S27: 45600 | T27: 45601 | U27: 45602 | V27: 45603 | W27: 45604 | X27: 45605 | Y27: 45606 | AA27: 45628 | AB27: 45629 | AC27: 45630 | AD27: 45631 | AE27: 45632 | AF27: 45633 | AG27: 45634 | AI27: =Calc!R34 | AJ27: =Calc!S34
C28: 45544 | D28: 45545 | E28: 45546 | F28: 45547 | G28: 45548 | H28: 45549 | I28: 45550 | K28: 45579 | L28: 45580 | M28: 45581 | N28: 45582 | O28: 45583 | P28: 45584 | Q28: 45585 | S28: 45607 | T28: 45608 | U28: 45609 | V28: 45610 | W28: 45611 | X28: 45612 | Y28: 45613 | AA28: 45635 | AB28: 45636 | AC28: 45637 | AD28: 45638 | AE28: 45639 | AF28: 45640 | AG28: 45641 | AI28: =Calc!R35 | AJ28: =Calc!S35
C29: 45551 | D29: 45552 | E29: 45553 | F29: 45554 | G29: 45555 | H29: 45556 | I29: 45557 | K29: 45586 | L29: 45587 | M29: 45588 | N29: 45589 | O29: 45590 | P29: 45591 | Q29: 45592 | S29: 45614 | T29: 45615 | U29: 45616 | V29: 45617 | W29: 45618 | X29: 45619 | Y29: 45620 | AA29: 45642 | AB29: 45643 | AC29: 45644 | AD29: 45645 | AE29: 45646 | AF29: 45647 | AG29: 45648 | AI29: =Calc!R36 | AJ29: =Calc!S36
C30: 45558 | D30: 45559 | E30: 45560 | F30: 45561 | G30: 45562 | H30: 45563 | I30: 45564 | K30: 45593 | L30: 45594 | M30: 45595 | N30: 45596 | S30: 45621 | T30: 45622 | U30: 45623 | V30: 45624 | W30: 45625 | X30: 45626 | AA30: 45649 | AB30: 45650 | AC30: 45651 | AD30: 45652 | AE30: 45653 | AF30: 45654 | AG30: 45655 | AI30: =Calc!R37 | AJ30: =Calc!S37
C31: 45565 | AA31: 45656 | AB31: 45657

Sheet Any Month
C1: Any Month Calendar
C3: 1 | D3: ← Pick a month
C5: =TEXT(C9,"MMMM YYYY") -> January 2024
C6: =LEFT(TEXT(C9,"DDD"),1) -> M | D6: =LEFT(TEXT(D9,"DDD"),1) -> T | E6: =LEFT(TEXT(E9,"DDD"),1) -> W | F6: =LEFT(TEXT(F9,"DDD"),1) -> T | G6: =LEFT(TEXT(G9,"DDD"),1) -> F | H6: =LEFT(TEXT(H9,"DDD"),1) -> S | I6: =LEFT(TEXT(I9,"DDD"),1) -> S
C7: =Calc!Z13 -> 45292 | D7: =Calc!AA13 -> 45293 | E7: =Calc!AB13 -> 45294 | F7: =Calc!AC13 -> 45295 | G7: =Calc!AD13 -> 45296 | H7: =Calc!AE13 -> 45297 | I7: =Calc!AF13 -> 45298
C8: =Calc!Z31 | D8: =Calc!AA31 | E8: =Calc!AB31 | F8: =Calc!AC31 | G8: =Calc!AD31 | H8: =Calc!AE31 | I8: =Calc!AF31
C9: =Calc!Z14 -> 45299 | D9: =Calc!AA14 -> 45300 | E9: =Calc!AB14 -> 45301 | F9: =Calc!AC14 -> 45302 | G9: =Calc!AD14 -> 45303 | H9: =Calc!AE14 -> 45304 | I9: =Calc!AF14 -> 45305
C10: =Calc!Z32 | D10: =Calc!AA32 | E10: =Calc!AB32 -> ✈Flight to Wellington 🎉Another Thing | F10: =Calc!AC32 | G10: =Calc!AD32 | H10: =Calc!AE32 | I10: =Calc!AF32
C11: =Calc!Z15 -> 45306 | D11: =Calc!AA15 -> 45307 | E11: =Calc!AB15 -> 45308 | F11: =Calc!AC15 -> 45309 | G11: =Calc!AD15 -> 45310 | H11: =Calc!AE15 -> 45311 | I11: =Calc!AF15 -> 45312
C12: =Calc!Z33 | D12: =Calc!AA33 | E12: =Calc!AB33 | F12: =Calc!AC33 | G12: =Calc!AD33 | H12: =Calc!AE33 | I12: =Calc!AF33 -> 🎂Wedding Anniversary
C13: =Calc!Z16 -> 45313 | D13: =Calc!AA16 -> 45314 | E13: =Calc!AB16 -> 45315 | F13: =Calc!AC16 -> 45316 | G13: =Calc!AD16 -> 45317 | H13: =Calc!AE16 -> 45318 | I13: =Calc!AF16 -> 45319
C14: =Calc!Z34 | D14: =Calc!AA34 | E14: =Calc!AB34 | F14: =Calc!AC34 | G14: =Calc!AD34 | H14: =Calc!AE34 | I14: =Calc!AF34
C15: =Calc!Z17 -> 45320 | D15: =Calc!AA17 -> 45321 | E15: =Calc!AB17 -> 45322 | F15: =Calc!AC17 | G15: =Calc!AD17 | H15: =Calc!AE17 | I15: =Calc!AF17
C16: =Calc!Z35 -> 👨‍👧‍👦School Reopens ⏱Order Team Lunches | D16: =Calc!AA35 | E16: =Calc!AB35 | F16: =Calc!AC35 | G16: =Calc!AD35 | H16: =Calc!AE35 | I16: =Calc!AF35
C17: =Calc!Z18 | D17: =Calc!AA18 | E17: =Calc!AB18 | F17: =Calc!AC18 | G17: =Calc!AD18 | H17: =Calc!AE18 | I17: =Calc!AF18
C18: =Calc!Z36 | D18: =Calc!AA36 | E18: =Calc!AB36 | F18: =Calc!AC36 | G18: =Calc!AD36 | H18: =Calc!AE36 | I18: =Calc!AF36

Sheet Planner
C1: Set up your Planner here
C4: Date | D4: Activity | E4: Type
C5: 45301 | D5: Flight to Wellington | E5: Travel
C6: 45312 | D6: Wedding Anniversary | E6: Anniversaries
C7: 45320 | D7: School Reopens | E7: Kids stuff
C8: 45328 | D8: Flight to London | E8: Work stuff
C9: 45348 | D9: University Term Starts | E9: Appointment
C10: 45395 | D10: Term Break | E10: Party
C11: 45479 | D11: Fiji Holiday | E11: Travel
C12: 45559 | D12: Kids Birthday | E12: Anniversaries
C13: 45301 | D13: Another Thing | E13: Party
C14: 45320 | D14: Order Team Lunches | E14: Appointment

Sheet Customizations
B1: Customizations
F3: Icon options | J3: Holiday List
B4: Year | C4: 2024 | D4: Change this to see calendar for another year | F4: Icon | G4: Type | J4: Date | K4: Holiday
B5: Week start | C5: 1 | D5: (1 for Monday, 7 for Sunday) | F5: 🎂 | G5: Anniversaries | J5: 45292 | K5: New Year's Day
B6: Weekend | C6: 1 | D6: (1 for Sat+Sun, 2 for Sun+Mon… 11 for Sun only, 12 for Mon only) | F6: ⏱ | G6: Appointment | J6: 45306 | K6: Martin Luther King Jr. Birthday
B7: Highlight Planner Dates? | C7: Yes | F7: 🏠 | G7: Home stuff | J7: 45341 | K7: President's Day
F8: 🎉 | G8: Party | J8: 45439 | K8: Memorial Day
F9: ✈ | G9: Travel | J9: 45462 | K9: Juneteenth
F10: 📺 | G10: Video | J10: 45477 | K10: Independence Day
F11: 🏢 | G11: Work stuff | J11: 45537 | K11: Labor Day
F12: 👨‍👧‍👦 | G12: Kids stuff | J12: 45579 | K12: Columbus Day
J13: 45607 | K13: Veterans Day
J14: 45624 | K14: Thanksgiving Day
J15: 45651 | K15: Christmas Day

Sheet Calc
C1: Calculations - Do not edit
C8: 1 | E8: =DATE(cal.year,C8,1) -> 45292 | F8: =WEEKDAY(E8,week.start+10) -> 1 | H8: =E8 -> 45292 | N8: Today | O8: =TODAY() -> 45314
E9: prev. weekstart | H9: =E8-F8+1 -> 45292
N10: Next Activities | R10: For the Calendar (show only first 25) | V10: Month numbers (for drop down) | Z10: Selected Month | AA10: ='Any Month'!C3 -> 1
D12: =TEXT(D13,"DDD") -> Mon | E12: =TEXT(E13,"DDD") -> Tue | F12: =TEXT(F13,"DDD") -> Wed | G12: =TEXT(G13,"DDD") -> Thu | H12: =TEXT(H13,"DDD") -> Fri | I12: =TEXT(I13,"DDD") -> Sat | J12: =TEXT(J13,"DDD") -> Sun | K12: WEEKNUM | N12: Date | O12: Activity | P12: Type | R12: Type Icon | S12: Date & Activity | V12: Month | Z12: Calendar
C13: 1 | D13: {=_xlfn.LET(_xlpm.mStart, DATE(cal.year, C13, 1), _xlpm.wDay, WEEKDAY(_xlpm.mStart, 10+week.start), _xlfn.SEQUENCE(6,7,_xlpm.mStart-_xlpm.wDay+1))} -> 45292 | E13: 45293 | F13: 45294 | G13: 45295 | H13: 45296 | I13: 45297 | J13: 45298 | K13: =WEEKNUM(D13,10+week.start) -> 1 | N13: {=_xlfn._xlws.SORT(_xlfn._xlws.FILTER(Plan[], Plan[Date]>=O8),1)} -> 45320 | O13: School Reopens | P13: Kids stuff | R13: =_xlfn.XLOOKUP(P13,icons[Type],icons[Icon],"") -> 👨‍👧‍👦 | S13: =IF(N13=0,"",TEXT(N13,"d-mmm")&": "&O13) -> 29-Jan: School Reopens | V13: {=_xlfn.SEQUENCE(12)} -> 1 | Z13: {=_xlfn.LET(_xlpm.dt, _xlfn._xlws.FILTER(monthly.calendar, month.nums=AA10), IF(MONTH(_xlpm.dt)<>AA10,"",_xlpm.dt))} -> 45292 | AA13: 45293 | AB13: 45294 | AC13: 45295 | AD13: 45296 | AE13: 45297 | AF13: 45298
C14: =C13 -> 1 | D14: 45299 | E14: 45300 | F14: 45301 | G14: 45302 | H14: 45303 | I14: 45304 | J14: 45305 | K14: =WEEKNUM(D14,10+week.start) -> 2 | N14: 45320 | O14: Order Team Lunches | P14: Appointment | R14: =_xlfn.XLOOKUP(P14,icons[Type],icons[Icon],"") -> ⏱ | S14: =IF(N14=0,"",TEXT(N14,"d-mmm")&": "&O14) -> 29-Jan: Order Team Lunches | V14: 2 | Z14: 45299 | AA14: 45300 | AB14: 45301 | AC14: 45302 | AD14: 45303 | AE14: 45304 | AF14: 45305
C15: =C14 -> 1 | D15: 45306 | E15: 45307 | F15: 45308 | G15: 45309 | H15: 45310 | I15: 45311 | J15: 45312 | K15: =WEEKNUM(D15,10+week.start) -> 3 | N15: 45328 | O15: Flight to London | P15: Work stuff | R15: =_xlfn.XLOOKUP(P15,icons[Type],icons[Icon],"") -> 🏢 | S15: =IF(N15=0,"",TEXT(N15,"d-mmm")&": "&O15) -> 6-Feb: Flight to London | V15: 3 | Z15: 45306 | AA15: 45307 | AB15: 45308 | AC15: 45309 | AD15: 45310 | AE15: 45311 | AF15: 45312
C16: =C15 -> 1 | D16: 45313 | E16: 45314 | F16: 45315 | G16: 45316 | H16: 45317 | I16: 45318 | J16: 45319 | K16: =WEEKNUM(D16,10+week.start) -> 4 | N16: 45348 | O16: University Term Starts | P16: Appointment | R16: =_xlfn.XLOOKUP(P16,icons[Type],icons[Icon],"") -> ⏱ | S16: =IF(N16=0,"",TEXT(N16,"d-mmm")&": "&O16) -> 26-Feb: University Term Starts | V16: 4 | Z16: 45313 | AA16: 45314 | AB16: 45315 | AC16: 45316 | AD16: 45317 | AE16: 45318 | AF16: 45319
C17: =C16 -> 1 | D17: 45320 | E17: 45321 | F17: 45322 | G17: 45323 | H17: 45324 | I17: 45325 | J17: 45326 | K17: =WEEKNUM(D17,10+week.start) -> 5 | N17: 45395 | O17: Term Break | P17: Party | R17: =_xlfn.XLOOKUP(P17,icons[Type],icons[Icon],"") -> 🎉 | S17: =IF(N17=0,"",TEXT(N17,"d-mmm")&": "&O17) -> 13-Apr: Term Break | V17: 5 | Z17: 45320 | AA17: 45321 | AB17: 45322
C18: =C17 -> 1 | D18: 45327 | E18: 45328 | F18: 45329 | G18: 45330 | H18: 45331 | I18: 45332 | J18: 45333 | K18: =WEEKNUM(D18,10+week.start) -> 6 | N18: 45479 | O18: Fiji Holiday | P18: Travel | R18: =_xlfn.XLOOKUP(P18,icons[Type],icons[Icon],"") -> ✈ | S18: =IF(N18=0,"",TEXT(N18,"d-mmm")&": "&O18) -> 6-Jul: Fiji Holiday | V18: 6
C19: =C13+1 -> 2 | D19: {=_xlfn.LET(_xlpm.mStart, DATE(cal.year, C19, 1), _xlpm.wDay, WEEKDAY(_xlpm.mStart, 10+week.start), _xlfn.SEQUENCE(6,7,_xlpm.mStart-_xlpm.wDay+1))} -> 45320 | E19: 45321 | F19: 45322 | G19: 45323 | H19: 45324 | I19: 45325 | J19: 45326 | K19: =WEEKNUM(D19,10+week.start) -> 5 | N19: 45559 | O19: Kids Birthday | P19: Anniversaries | R19: =_xlfn.XLOOKUP(P19,icons[Type],icons[Icon],"") -> 🎂 | S19: =IF(N19=0,"",TEXT(N19,"d-mmm")&": "&O19) -> 24-Sep: Kids Birthday | V19: 7
C20: =C19 -> 2 | D20: 45327 | E20: 45328 | F20: 45329 | G20: 45330 | H20: 45331 | I20: 45332 | J20: 45333 | K20: =WEEKNUM(D20,10+week.start) -> 6 | R20: =_xlfn.XLOOKUP(P20,icons[Type],icons[Icon],"") | S20: =IF(N20=0,"",TEXT(N20,"d-mmm")&": "&O20) | V20: 8
C21: =C20 -> 2 | D21: 45334 | E21: 45335 | F21: 45336 | G21: 45337 | H21: 45338 | I21: 45339 | J21: 45340 | K21: =WEEKNUM(D21,10+week.start) -> 7 | R21: =_xlfn.XLOOKUP(P21,icons[Type],icons[Icon],"") | S21: =IF(N21=0,"",TEXT(N21,"d-mmm")&": "&O21) | V21: 9 | Z21: Acts
C22: =C21 -> 2 | D22: 45341 | E22: 45342 | F22: 45343 | G22: 45344 | H22: 45345 | I22: 45346 | J22: 45347 | K22: =WEEKNUM(D22,10+week.start) -> 8 | R22: =_xlfn.XLOOKUP(P22,icons[Type],icons[Icon],"") | S22: =IF(N22=0,"",TEXT(N22,"d-mmm")&": "&O22) | V22: 10 | Z22: {=IFERROR(_xlfn.XLOOKUP(_xlfn.MAP(_xlfn.ANCHORARRAY(Z13),_xlfn.LAMBDA(_xlpm.v, _xlfn._xlws.FILTER(Plan[Type],Plan[Date]=_xlpm.v,""))),icons[Type],icons[Icon])&" "&_xlfn.MAP(_xlfn.ANCHORARRAY(Z13),_xlfn.LAMBDA(_xlpm.v, _xlfn._xlws.FILTER(Plan[Activity],Plan[Date]=_xlpm.v,""))),"")}
C23: =C22 -> 2 | D23: 45348 | E23: 45349 | F23: 45350 | G23: 45351 | H23: 45352 | I23: 45353 | J23: 45354 | K23: =WEEKNUM(D23,10+week.start) -> 9 | R23: =_xlfn.XLOOKUP(P23,icons[Type],icons[Icon],"") | S23: =IF(N23=0,"",TEXT(N23,"d-mmm")&": "&O23) | V23: 11
C24: =C23 -> 2 | D24: 45355 | E24: 45356 | F24: 45357 | G24: 45358 | H24: 45359 | I24: 45360 | J24: 45361 | K24: =WEEKNUM(D24,10+week.start) -> 10 | R24: =_xlfn.XLOOKUP(P24,icons[Type],icons[Icon],"") | S24: =IF(N24=0,"",TEXT(N24,"d-mmm")&": "&O24) | V24: 12
C25: =C19+1 -> 3 | D25: {=_xlfn.LET(_xlpm.mStart, DATE(cal.year, C25, 1), _xlpm.wDay, WEEKDAY(_xlpm.mStart, 10+week.start), _xlfn.SEQUENCE(6,7,_xlpm.mStart-_xlpm.wDay+1))} -> 45348 | E25: 45349 | F25: 45350 | G25: 45351 | H25: 45352 | I25: 45353 | J25: 45354 | K25: =WEEKNUM(D25,10+week.start) -> 9 | R25: =_xlfn.XLOOKUP(P25,icons[Type],icons[Icon],"") | S25: =IF(N25=0,"",TEXT(N25,"d-mmm")&": "&O25)
C26: =C25 -> 3 | D26: 45355 | E26: 45356 | F26: 45357 | G26: 45358 | H26: 45359 | I26: 45360 | J26: 45361 | K26: =WEEKNUM(D26,10+week.start) -> 10 | R26: =_xlfn.XLOOKUP(P26,icons[Type],icons[Icon],"") | S26: =IF(N26=0,"",TEXT(N26,"d-mmm")&": "&O26)
C27: =C26 -> 3 | D27: 45362 | E27: 45363 | F27: 45364 | G27: 45365 | H27: 45366 | I27: 45367 | J27: 45368 | K27: =WEEKNUM(D27,10+week.start) -> 11 | R27: =_xlfn.XLOOKUP(P27,icons[Type],icons[Icon],"") | S27: =IF(N27=0,"",TEXT(N27,"d-mmm")&": "&O27)
C28: =C27 -> 3 | D28: 45369 | E28: 45370 | F28: 45371 | G28: 45372 | H28: 45373 | I28: 45374 | J28: 45375 | K28: =WEEKNUM(D28,10+week.start) -> 12 | R28: =_xlfn.XLOOKUP(P28,icons[Type],icons[Icon],"") | S28: =IF(N28=0,"",TEXT(N28,"d-mmm")&": "&O28)
C29: =C28 -> 3 | D29: 45376 | E29: 45377 | F29: 45378 | G29: 45379 | H29: 45380 | I29: 45381 | J29: 45382 | K29: =WEEKNUM(D29,10+week.start) -> 13 | R29: =_xlfn.XLOOKUP(P29,icons[Type],icons[Icon],"") | S29: =IF(N29=0,"",TEXT(N29,"d-mmm")&": "&O29)
C30: =C29 -> 3 | D30: 45383 | E30: 45384 | F30: 45385 | G30: 45386 | H30: 45387 | I30: 45388 | J30: 45389 | K30: =WEEKNUM(D30,10+week.start) -> 14 | R30: =_xlfn.XLOOKUP(P30,icons[Type],icons[Icon],"") | S30: =IF(N30=0,"",TEXT(N30,"d-mmm")&": "&O30)
C31: =C25+1 -> 4 | D31: {=_xlfn.LET(_xlpm.mStart, DATE(cal.year, C31, 1), _xlpm.wDay, WEEKDAY(_xlpm.mStart, 10+week.start), _xlfn.SEQUENCE(6,7,_xlpm.mStart-_xlpm.wDay+1))} -> 45383 | E31: 45384 | F31: 45385 | G31: 45386 | H31: 45387 | I31: 45388 | J31: 45389 | K31: =WEEKNUM(D31,10+week.start) -> 14 | R31: =_xlfn.XLOOKUP(P31,icons[Type],icons[Icon],"") | S31: =IF(N31=0,"",TEXT(N31,"d-mmm")&": "&O31) | Z31: {=IFERROR(_xlfn.LET(_xlpm.events, _xlfn._xlws.FILTER(Plan[Activity],Plan[Date]=Calc!Z13), _xlpm.ic, _xlfn.XLOOKUP(_xlfn._xlws.FILTER(Plan[Type], Plan[Date]=Z13,"x"), icons[Type], icons[Icon]), _xlfn.TEXTJOIN(CHAR(10),TRUE, _xlpm.ic&_xlpm.events)),"")} | AA31: {=IFERROR(_xlfn.LET(_xlpm.events, _xlfn._xlws.FILTER(Plan[Activity],Plan[Date]=Calc!AA13), _xlpm.ic, _xlfn.XLOOKUP(_xlfn._xlws.FILTER(Plan[Type], Plan[Date]=AA13,"x"), icons[Type], icons[Icon]), _xlfn.TEXTJOIN(CHAR(10),TRUE, _xlpm.ic&_xlpm.events)),"")} | AB31: {=IFERROR(_xlfn.LET(_xlpm.events, _xlfn._xlws.FILTER(Plan[Activity],Plan[Date]=Calc!AB13), _xlpm.ic, _xlfn.XLOOKUP(_xlfn._xlws.FILTER(Plan[Type], Plan[Date]=AB13,"x"), icons[Type], icons[Icon]), _xlfn.TEXTJOIN(CHAR(10),TRUE, _xlpm.ic&_xlpm.events)),"")} | AC31: {=IFERROR(_xlfn.LET(_xlpm.events, _xlfn._xlws.FILTER(Plan[Activity],Plan[Date]=Calc!AC13), _xlpm.ic, _xlfn.XLOOKUP(_xlfn._xlws.FILTER(Plan[Type], Plan[Date]=AC13,"x"), icons[Type], icons[Icon]), _xlfn.TEXTJOIN(CHAR(10),TRUE, _xlpm.ic&_xlpm.events)),"")} | AD31: {=IFERROR(_xlfn.LET(_xlpm.events, _xlfn._xlws.FILTER(Plan[Activity],Plan[Date]=Calc!AD13), _xlpm.ic, _xlfn.XLOOKUP(_xlfn._xlws.FILTER(Plan[Type], Plan[Date]=AD13,"x"), icons[Type], icons[Icon]), _xlfn.TEXTJOIN(CHAR(10),TRUE, _xlpm.ic&_xlpm.events)),"")} | AE31: {=IFERROR(_xlfn.LET(_xlpm.events, _xlfn._xlws.FILTER(Plan[Activity],Plan[Date]=Calc!AE13), _xlpm.ic, _xlfn.XLOOKUP(_xlfn._xlws.FILTER(Plan[Type], Plan[Date]=AE13,"x"), icons[Type], icons[Icon]), _xlfn.TEXTJOIN(CHAR(10),TRUE, _xlpm.ic&_xlpm.events)),"")} | AF31: {=IFERROR(_xlfn.LET(_xlpm.events, _xlfn._xlws.FILTER(Plan[Activity],Plan[Date]=Calc!AF13), _xlpm.ic, _xlfn.XLOOKUP(_xlfn._xlws.FILTER(Plan[Type], Plan[Date]=AF13,"x"), icons[Type], icons[Icon]), _xlfn.TEXTJOIN(CHAR(10),TRUE, _xlpm.ic&_xlpm.events)),"")}
C32: =C31 -> 4 | D32: 45390 | E32: 45391 | F32: 45392 | G32: 45393 | H32: 45394 | I32: 45395 | J32: 45396 | K32: =WEEKNUM(D32,10+week.start) -> 15 | R32: =_xlfn.XLOOKUP(P32,icons[Type],icons[Icon],"") | S32: =IF(N32=0,"",TEXT(N32,"d-mmm")&": "&O32) | Z32: {=IFERROR(_xlfn.LET(_xlpm.events, _xlfn._xlws.FILTER(Plan[Activity],Plan[Date]=Calc!Z14), _xlpm.ic, _xlfn.XLOOKUP(_xlfn._xlws.FILTER(Plan[Type], Plan[Date]=Z14,"x"), icons[Type], icons[Icon]), _xlfn.TEXTJOIN(CHAR(10),TRUE, _xlpm.ic&_xlpm.events)),"")} | AA32: {=IFERROR(_xlfn.LET(_xlpm.events, _xlfn._xlws.FILTER(Plan[Activity],Plan[Date]=Calc!AA14), _xlpm.ic, _xlfn.XLOOKUP(_xlfn._xlws.FILTER(Plan[Type], Plan[Date]=AA14,"x"), icons[Type], icons[Icon]), _xlfn.TEXTJOIN(CHAR(10),TRUE, _xlpm.ic&_xlpm.events)),"")} | AB32: {=IFERROR(_xlfn.LET(_xlpm.events, _xlfn._xlws.FILTER(Plan[Activity],Plan[Date]=Calc!AB14), _xlpm.ic, _xlfn.XLOOKUP(_xlfn._xlws.FILTER(Plan[Type], Plan[Date]=AB14,"x"), icons[Type], icons[Icon]), _xlfn.TEXTJOIN(CHAR(10),TRUE, _xlpm.ic&_xlpm.events)),"")} -> ✈Flight to Wellington 🎉Another Thing | AC32: {=IFERROR(_xlfn.LET(_xlpm.events, _xlfn._xlws.FILTER(Plan[Activity],Plan[Date]=Calc!AC14), _xlpm.ic, _xlfn.XLOOKUP(_xlfn._xlws.FILTER(Plan[Type], Plan[Date]=AC14,"x"), icons[Type], icons[Icon]), _xlfn.TEXTJOIN(CHAR(10),TRUE, _xlpm.ic&_xlpm.events)),"")} | AD32: {=IFERROR(_xlfn.LET(_xlpm.events, _xlfn._xlws.FILTER(Plan[Activity],Plan[Date]=Calc!AD14), _xlpm.ic, _xlfn.XLOOKUP(_xlfn._xlws.FILTER(Plan[Type], Plan[Date]=AD14,"x"), icons[Type], icons[Icon]), _xlfn.TEXTJOIN(CHAR(10),TRUE, _xlpm.ic&_xlpm.events)),"")} | AE32: {=IFERROR(_xlfn.LET(_xlpm.events, _xlfn._xlws.FILTER(Plan[Activity],Plan[Date]=Calc!AE14), _xlpm.ic, _xlfn.XLOOKUP(_xlfn._xlws.FILTER(Plan[Type], Plan[Date]=AE14,"x"), icons[Type], icons[Icon]), _xlfn.TEXTJOIN(CHAR(10),TRUE, _xlpm.ic&_xlpm.events)),"")} | AF32: {=IFERROR(_xlfn.LET(_xlpm.events, _xlfn._xlws.FILTER(Plan[Activity],Plan[Date]=Calc!AF14), _xlpm.ic, _xlfn.XLOOKUP(_xlfn._xlws.FILTER(Plan[Type], Plan[Date]=AF14,"x"), icons[Type], icons[Icon]), _xlfn.TEXTJOIN(CHAR(10),TRUE, _xlpm.ic&_xlpm.events)),"")}
C33: =C32 -> 4 | D33: 45397 | E33: 45398 | F33: 45399 | G33: 45400 | H33: 45401 | I33: 45402 | J33: 45403 | K33: =WEEKNUM(D33,10+week.start) -> 16 | R33: =_xlfn.XLOOKUP(P33,icons[Type],icons[Icon],"") | S33: =IF(N33=0,"",TEXT(N33,"d-mmm")&": "&O33) | Z33: {=IFERROR(_xlfn.LET(_xlpm.events, _xlfn._xlws.FILTER(Plan[Activity],Plan[Date]=Calc!Z15), _xlpm.ic, _xlfn.XLOOKUP(_xlfn._xlws.FILTER(Plan[Type], Plan[Date]=Z15,"x"), icons[Type], icons[Icon]), _xlfn.TEXTJOIN(CHAR(10),TRUE, _xlpm.ic&_xlpm.events)),"")} | AA33: {=IFERROR(_xlfn.LET(_xlpm.events, _xlfn._xlws.FILTER(Plan[Activity],Plan[Date]=Calc!AA15), _xlpm.ic, _xlfn.XLOOKUP(_xlfn._xlws.FILTER(Plan[Type], Plan[Date]=AA15,"x"), icons[Type], icons[Icon]), _xlfn.TEXTJOIN(CHAR(10),TRUE, _xlpm.ic&_xlpm.events)),"")} | AB33: {=IFERROR(_xlfn.LET(_xlpm.events, _xlfn._xlws.FILTER(Plan[Activity],Plan[Date]=Calc!AB15), _xlpm.ic, _xlfn.XLOOKUP(_xlfn._xlws.FILTER(Plan[Type], Plan[Date]=AB15,"x"), icons[Type], icons[Icon]), _xlfn.TEXTJOIN(CHAR(10),TRUE, _xlpm.ic&_xlpm.events)),"")} | AC33: {=IFERROR(_xlfn.LET(_xlpm.events, _xlfn._xlws.FILTER(Plan[Activity],Plan[Date]=Calc!AC15), _xlpm.ic, _xlfn.XLOOKUP(_xlfn._xlws.FILTER(Plan[Type], Plan[Date]=AC15,"x"), icons[Type], icons[Icon]), _xlfn.TEXTJOIN(CHAR(10),TRUE, _xlpm.ic&_xlpm.events)),"")} | AD33: {=IFERROR(_xlfn.LET(_xlpm.events, _xlfn._xlws.FILTER(Plan[Activity],Plan[Date]=Calc!AD15), _xlpm.ic, _xlfn.XLOOKUP(_xlfn._xlws.FILTER(Plan[Type], Plan[Date]=AD15,"x"), icons[Type], icons[Icon]), _xlfn.TEXTJOIN(CHAR(10),TRUE, _xlpm.ic&_xlpm.events)),"")} | AE33: {=IFERROR(_xlfn.LET(_xlpm.events, _xlfn._xlws.FILTER(Plan[Activity],Plan[Date]=Calc!AE15), _xlpm.ic, _xlfn.XLOOKUP(_xlfn._xlws.FILTER(Plan[Type], Plan[Date]=AE15,"x"), icons[Type], icons[Icon]), _xlfn.TEXTJOIN(CHAR(10),TRUE, _xlpm.ic&_xlpm.events)),"")} | AF33: {=IFERROR(_xlfn.LET(_xlpm.events, _xlfn._xlws.FILTER(Plan[Activity],Plan[Date]=Calc!AF15), _xlpm.ic, _xlfn.XLOOKUP(_xlfn._xlws.FILTER(Plan[Type], Plan[Date]=AF15,"x"), icons[Type], icons[Icon]), _xlfn.TEXTJOIN(CHAR(10),TRUE, _xlpm.ic&_xlpm.events)),"")} -> 🎂Wedding Anniversary
C34: =C33 -> 4 | D34: 45404 | E34: 45405 | F34: 45406 | G34: 45407 | H34: 45408 | I34: 45409 | J34: 45410 | K34: =WEEKNUM(D34,10+week.start) -> 17 | R34: =_xlfn.XLOOKUP(P34,icons[Type],icons[Icon],"") | S34: =IF(N34=0,"",TEXT(N34,"d-mmm")&": "&O34) | Z34: {=IFERROR(_xlfn.LET(_xlpm.events, _xlfn._xlws.FILTER(Plan[Activity],Plan[Date]=Calc!Z16), _xlpm.ic, _xlfn.XLOOKUP(_xlfn._xlws.FILTER(Plan[Type], Plan[Date]=Z16,"x"), icons[Type], icons[Icon]), _xlfn.TEXTJOIN(CHAR(10),TRUE, _xlpm.ic&_xlpm.events)),"")} | AA34: {=IFERROR(_xlfn.LET(_xlpm.events, _xlfn._xlws.FILTER(Plan[Activity],Plan[Date]=Calc!AA16), _xlpm.ic, _xlfn.XLOOKUP(_xlfn._xlws.FILTER(Plan[Type], Plan[Date]=AA16,"x"), icons[Type], icons[Icon]), _xlfn.TEXTJOIN(CHAR(10),TRUE, _xlpm.ic&_xlpm.events)),"")} | AB34: {=IFERROR(_xlfn.LET(_xlpm.events, _xlfn._xlws.FILTER(Plan[Activity],Plan[Date]=Calc!AB16), _xlpm.ic, _xlfn.XLOOKUP(_xlfn._xlws.FILTER(Plan[Type], Plan[Date]=AB16,"x"), icons[Type], icons[Icon]), _xlfn.TEXTJOIN(CHAR(10),TRUE, _xlpm.ic&_xlpm.events)),"")} | AC34: {=IFERROR(_xlfn.LET(_xlpm.events, _xlfn._xlws.FILTER(Plan[Activity],Plan[Date]=Calc!AC16), _xlpm.ic, _xlfn.XLOOKUP(_xlfn._xlws.FILTER(Plan[Type], Plan[Date]=AC16,"x"), icons[Type], icons[Icon]), _xlfn.TEXTJOIN(CHAR(10),TRUE, _xlpm.ic&_xlpm.events)),"")} | AD34: {=IFERROR(_xlfn.LET(_xlpm.events, _xlfn._xlws.FILTER(Plan[Activity],Plan[Date]=Calc!AD16), _xlpm.ic, _xlfn.XLOOKUP(_xlfn._xlws.FILTER(Plan[Type], Plan[Date]=AD16,"x"), icons[Type], icons[Icon]), _xlfn.TEXTJOIN(CHAR(10),TRUE, _xlpm.ic&_xlpm.events)),"")} | AE34: {=IFERROR(_xlfn.LET(_xlpm.events, _xlfn._xlws.FILTER(Plan[Activity],Plan[Date]=Calc!AE16), _xlpm.ic, _xlfn.XLOOKUP(_xlfn._xlws.FILTER(Plan[Type], Plan[Date]=AE16,"x"), icons[Type], icons[Icon]), _xlfn.TEXTJOIN(CHAR(10),TRUE, _xlpm.ic&_xlpm.events)),"")} | AF34: {=IFERROR(_xlfn.LET(_xlpm.events, _xlfn._xlws.FILTER(Plan[Activity],Plan[Date]=Calc!AF16), _xlpm.ic, _xlfn.XLOOKUP(_xlfn._xlws.FILTER(Plan[Type], Plan[Date]=AF16,"x"), icons[Type], icons[Icon]), _xlfn.TEXTJOIN(CHAR(10),TRUE, _xlpm.ic&_xlpm.events)),"")}
C35: =C34 -> 4 | D35: 45411 | E35: 45412 | F35: 45413 | G35: 45414 | H35: 45415 | I35: 45416 | J35: 45417 | K35: =WEEKNUM(D35,10+week.start) -> 18 | R35: =_xlfn.XLOOKUP(P35,icons[Type],icons[Icon],"") | S35: =IF(N35=0,"",TEXT(N35,"d-mmm")&": "&O35) | Z35: {=IFERROR(_xlfn.LET(_xlpm.events, _xlfn._xlws.FILTER(Plan[Activity],Plan[Date]=Calc!Z17), _xlpm.ic, _xlfn.XLOOKUP(_xlfn._xlws.FILTER(Plan[Type], Plan[Date]=Z17,"x"), icons[Type], icons[Icon]), _xlfn.TEXTJOIN(CHAR(10),TRUE, _xlpm.ic&_xlpm.events)),"")} -> 👨‍👧‍👦School Reopens ⏱Order Team Lunches | AA35: {=IFERROR(_xlfn.LET(_xlpm.events, _xlfn._xlws.FILTER(Plan[Activity],Plan[Date]=Calc!AA17), _xlpm.ic, _xlfn.XLOOKUP(_xlfn._xlws.FILTER(Plan[Type], Plan[Date]=AA17,"x"), icons[Type], icons[Icon]), _xlfn.TEXTJOIN(CHAR(10),TRUE, _xlpm.ic&_xlpm.events)),"")} | AB35: {=IFERROR(_xlfn.LET(_xlpm.events, _xlfn._xlws.FILTER(Plan[Activity],Plan[Date]=Calc!AB17), _xlpm.ic, _xlfn.XLOOKUP(_xlfn._xlws.FILTER(Plan[Type], Plan[Date]=AB17,"x"), icons[Type], icons[Icon]), _xlfn.TEXTJOIN(CHAR(10),TRUE, _xlpm.ic&_xlpm.events)),"")} | AC35: {=IFERROR(_xlfn.LET(_xlpm.events, _xlfn._xlws.FILTER(Plan[Activity],Plan[Date]=Calc!AC17), _xlpm.ic, _xlfn.XLOOKUP(_xlfn._xlws.FILTER(Plan[Type], Plan[Date]=AC17,"x"), icons[Type], icons[Icon]), _xlfn.TEXTJOIN(CHAR(10),TRUE, _xlpm.ic&_xlpm.events)),"")} | AD35: {=IFERROR(_xlfn.LET(_xlpm.events, _xlfn._xlws.FILTER(Plan[Activity],Plan[Date]=Calc!AD17), _xlpm.ic, _xlfn.XLOOKUP(_xlfn._xlws.FILTER(Plan[Type], Plan[Date]=AD17,"x"), icons[Type], icons[Icon]), _xlfn.TEXTJOIN(CHAR(10),TRUE, _xlpm.ic&_xlpm.events)),"")} | AE35: {=IFERROR(_xlfn.LET(_xlpm.events, _xlfn._xlws.FILTER(Plan[Activity],Plan[Date]=Calc!AE17), _xlpm.ic, _xlfn.XLOOKUP(_xlfn._xlws.FILTER(Plan[Type], Plan[Date]=AE17,"x"), icons[Type], icons[Icon]), _xlfn.TEXTJOIN(CHAR(10),TRUE, _xlpm.ic&_xlpm.events)),"")} | AF35: {=IFERROR(_xlfn.LET(_xlpm.events, _xlfn._xlws.FILTER(Plan[Activity],Plan[Date]=Calc!AF17), _xlpm.ic, _xlfn.XLOOKUP(_xlfn._xlws.FILTER(Plan[Type], Plan[Date]=AF17,"x"), icons[Type], icons[Icon]), _xlfn.TEXTJOIN(CHAR(10),TRUE, _xlpm.ic&_xlpm.events)),"")}
C36: =C35 -> 4 | D36: 45418 | E36: 45419 | F36: 45420 | G36: 45421 | H36: 45422 | I36: 45423 | J36: 45424 | K36: =WEEKNUM(D36,10+week.start) -> 19 | R36: =_xlfn.XLOOKUP(P36,icons[Type],icons[Icon],"") | S36: =IF(N36=0,"",TEXT(N36,"d-mmm")&": "&O36) | Z36: {=IFERROR(_xlfn.LET(_xlpm.events, _xlfn._xlws.FILTER(Plan[Activity],Plan[Date]=Calc!Z18), _xlpm.ic, _xlfn.XLOOKUP(_xlfn._xlws.FILTER(Plan[Type], Plan[Date]=Z18,"x"), icons[Type], icons[Icon]), _xlfn.TEXTJOIN(CHAR(10),TRUE, _xlpm.ic&_xlpm.events)),"")} | AA36: {=IFERROR(_xlfn.LET(_xlpm.events, _xlfn._xlws.FILTER(Plan[Activity],Plan[Date]=Calc!AA18), _xlpm.ic, _xlfn.XLOOKUP(_xlfn._xlws.FILTER(Plan[Type], Plan[Date]=AA18,"x"), icons[Type], icons[Icon]), _xlfn.TEXTJOIN(CHAR(10),TRUE, _xlpm.ic&_xlpm.events)),"")} | AB36: {=IFERROR(_xlfn.LET(_xlpm.events, _xlfn._xlws.FILTER(Plan[Activity],Plan[Date]=Calc!AB18), _xlpm.ic, _xlfn.XLOOKUP(_xlfn._xlws.FILTER(Plan[Type], Plan[Date]=AB18,"x"), icons[Type], icons[Icon]), _xlfn.TEXTJOIN(CHAR(10),TRUE, _xlpm.ic&_xlpm.events)),"")} | AC36: {=IFERROR(_xlfn.LET(_xlpm.events, _xlfn._xlws.FILTER(Plan[Activity],Plan[Date]=Calc!AC18), _xlpm.ic, _xlfn.XLOOKUP(_xlfn._xlws.FILTER(Plan[Type], Plan[Date]=AC18,"x"), icons[Type], icons[Icon]), _xlfn.TEXTJOIN(CHAR(10),TRUE, _xlpm.ic&_xlpm.events)),"")} | AD36: {=IFERROR(_xlfn.LET(_xlpm.events, _xlfn._xlws.FILTER(Plan[Activity],Plan[Date]=Calc!AD18), _xlpm.ic, _xlfn.XLOOKUP(_xlfn._xlws.FILTER(Plan[Type], Plan[Date]=AD18,"x"), icons[Type], icons[Icon]), _xlfn.TEXTJOIN(CHAR(10),TRUE, _xlpm.ic&_xlpm.events)),"")} | AE36: {=IFERROR(_xlfn.LET(_xlpm.events, _xlfn._xlws.FILTER(Plan[Activity],Plan[Date]=Calc!AE18), _xlpm.ic, _xlfn.XLOOKUP(_xlfn._xlws.FILTER(Plan[Type], Plan[Date]=AE18,"x"), icons[Type], icons[Icon]), _xlfn.TEXTJOIN(CHAR(10),TRUE, _xlpm.ic&_xlpm.events)),"")} | AF36: {=IFERROR(_xlfn.LET(_xlpm.events, _xlfn._xlws.FILTER(Plan[Activity],Plan[Date]=Calc!AF18), _xlpm.ic, _xlfn.XLOOKUP(_xlfn._xlws.FILTER(Plan[Type], Plan[Date]=AF18,"x"), icons[Type], icons[Icon]), _xlfn.TEXTJOIN(CHAR(10),TRUE, _xlpm.ic&_xlpm.events)),"")}
C37: =C31+1 -> 5 | D37: {=_xlfn.LET(_xlpm.mStart, DATE(cal.year, C37, 1), _xlpm.wDay, WEEKDAY(_xlpm.mStart, 10+week.start), _xlfn.SEQUENCE(6,7,_xlpm.mStart-_xlpm.wDay+1))} -> 45411 | E37: 45412 | F37: 45413 | G37: 45414 | H37: 45415 | I37: 45416 | J37: 45417 | K37: =WEEKNUM(D37,10+week.start) -> 18 | R37: =_xlfn.XLOOKUP(P37,icons[Type],icons[Icon],"") | S37: =IF(N37=0,"",TEXT(N37,"d-mmm")&": "&O37)
C38: =C37 -> 5 | D38: 45418 | E38: 45419 | F38: 45420 | G38: 45421 | H38: 45422 | I38: 45423 | J38: 45424 | K38: =WEEKNUM(D38,10+week.start) -> 19
C39: =C38 -> 5 | D39: 45425 | E39: 45426 | F39: 45427 | G39: 45428 | H39: 45429 | I39: 45430 | J39: 45431 | K39: =WEEKNUM(D39,10+week.start) -> 20
C40: =C39 -> 5 | D40: 45432 | E40: 45433 | F40: 45434 | G40: 45435 | H40: 45436 | I40: 45437 | J40: 45438 | K40: =WEEKNUM(D40,10+week.start) -> 21
C41: =C40 -> 5 | D41: 45439 | E41: 45440 | F41: 45441 | G41: 45442 | H41: 45443 | I41: 45444 | J41: 45445 | K41: =WEEKNUM(D41,10+week.start) -> 22
C42: =C41 -> 5 | D42: 45446 | E42: 45447 | F42: 45448 | G42: 45449 | H42: 45450 | I42: 45451 | J42: 45452 | K42: =WEEKNUM(D42,10+week.start) -> 23
C43: =C37+1 -> 6 | D43: {=_xlfn.LET(_xlpm.mStart, DATE(cal.year, C43, 1), _xlpm.wDay, WEEKDAY(_xlpm.mStart, 10+week.start), _xlfn.SEQUENCE(6,7,_xlpm.mStart-_xlpm.wDay+1))} -> 45439 | E43: 45440 | F43: 45441 | G43: 45442 | H43: 45443 | I43: 45444 | J43: 45445 | K43: =WEEKNUM(D43,10+week.start) -> 22
C44: =C43 -> 6 | D44: 45446 | E44: 45447 | F44: 45448 | G44: 45449 | H44: 45450 | I44: 45451 | J44: 45452 | K44: =WEEKNUM(D44,10+week.start) -> 23
C45: =C44 -> 6 | D45: 45453 | E45: 45454 | F45: 45455 | G45: 45456 | H45: 45457 | I45: 45458 | J45: 45459 | K45: =WEEKNUM(D45,10+week.start) -> 24
C46: =C45 -> 6 | D46: 45460 | E46: 45461 | F46: 45462 | G46: 45463 | H46: 45464 | I46: 45465 | J46: 45466 | K46: =WEEKNUM(D46,10+week.start) -> 25
C47: =C46 -> 6 | D47: 45467 | E47: 45468 | F47: 45469 | G47: 45470 | H47: 45471 | I47: 45472 | J47: 45473 | K47: =WEEKNUM(D47,10+week.start) -> 26
...
